Workbook
Name Slicer_Channel: #N/A
Name Slicer_Country: #N/A
Name Slicer_ProductCategory: #N/A
Name Slicer_Region: #N/A
Name Slicer_Salesperson: #N/A

Sheet Dashboard

Sheet Data
A1: OrderID | B1: OrderDate | C1: RequiredDate | D1: Region | E1: Country | F1: City | G1: CustomerSegment | H1: Channel | I1: Salesperson | J1: ProductCategory | K1: SKU | L1: UnitCost | M1: UnitPrice | N1: DiscountPct | O1: Quantity
A2: ORD-2024-275203 | B2: 45362 | C2: 45388 | D2: Africa | E2: Kenya | F2: Kisumu | G2: Corporate | H2: Retail | I2: C. Otieno | J2: Components | K2: CMP-8270 | L2: 279.24 | M2: 608.9 | N2: 0.112 | O2: 9
A3: ORD-2024-358795 | B3: 45588 | C3: 45587 | D3: Africa | E3: Nigeria | F3: Port Harcourt | G3: Education | H3: Online | I3: J. Njeri | J3: Printers | K3: PRN-9322 | L3: 1084.39 | M3: 759.33 | N3: 0.237 | O3: 31
A4: ORD-2023-373538 | B4: 44985 | C4: 45010 | D4: Africa | E4: Kenya | F4: Nairobi | G4: Corporate | H4: Retail | I4: I. Johnson | J4: Networking | K4: NET-9666 | L4: 1460.76 | M4: -30.66 | N4: 0.131 | O4: 12
A5: ORD-2025-168148 | B5: 45745 | C5: 45749 | D5: Africa | E5: Nigeria | F5: Lagos | G5: Non-Profit | H5: Marketplace | I5: G. Dubois | J5: Phones | K5: PHN-4556 | L5: 259.93 | M5: 255.94 | N5: 0.072 | O5: 22
A6: ORD-2023-824839 | B6: 45266 | C6: 45291 | D6: Asia | E6: Japan | F6: Osaka | G6: Consumer | H6: Retail | I6: L. Okafor | J6: Printers | K6: PRN-8041 | L6: 663.03 | M6: 813.51 | N6: 0.102 | O6: 15
A7: ORD-2023-723587 | B7: 44928 | C7: 44931 | D7: Americas | E7: Canada | F7: Toronto | G7: Corporate | H7: Distributor | I7: B. Chen | J7: Laptops | K7: LAP-8555 | L7: 315.87 | M7: 591.68 | N7: 0 | O7: 7
A8: ORD-2024-336584 | B8: 45653 | C8: 45671 | D8: Asia | E8: India | F8: Bengaluru | G8: Small Business | H8: Marketplace | I8: E. Garcia | J8: Monitors | K8: MON-8629 | L8: 586.07 | M8: 845.97 | N8: 0.147 | O8: 4
A9: ORD-2023-112666 | B9: 44941 | C9: 44939 | D9: Africa | E9: Nigeria | F9: Abuja | G9: Education | H9: Online | I9: O. Wang | J9: Printers | K9: PRN-6276 | L9: 28.38 | M9: 47.22 | N9: 0.194 | O9: 18
A10: ORD-2024-589570 | B10: 45416 | C10: 45441 | D10: Africa | E10: Nigeria | F10: Abuja | G10: Non-Profit | H10: Marketplace | I10: O. Wang | J10: Monitors | K10: MON-6892 | L10: 1295.34 | M10: 2530.81 | N10: 0.031 | O10: 6
A11: ORD-2025-997421 | B11: 45798 | C11: 45817 | D11: Americas | E11: Brazil | F11: São Paulo | G11: Non-Profit | H11: Online | I11: A. Patel | J11: Components | K11: CMP-3731 | L11: 1331.38 | M11: 2309.56 | N11: 0.149 | O11: 31
A12: ORD-2024-210687 | B12: 45319 | C12: 45331 | D12: Europe | E12: Germany | F12: Berlin | G12: Corporate | H12: Online | I12: G. Dubois | J12: Accessories | K12: ACC-7938 | L12: 644.17 | M12: 700.12 | N12: 0.006 | O12: 23
A13: ORD-2025-515515 | B13: 45660 | C13: 45680 | D13: Asia | E13: Japan | F13: Osaka | G13: Corporate | H13: Distributor | I13: F. Müller | J13: Phones | K13: PHN-7019 | L13: 908.6 | M13: 691.37 | N13: 0.25 | O13: 20
... A34: ORD-2025-474710 | B34: 45862 | C34: 45875 | D34: Africa | E34: South Africa | F34: Johannesburg | G34: Education | H34: Marketplace | I34: D. Smith | J34: Networking | K34: NET-7966 | L34: 1463.9 | M34: 2633.02 | N34: 0.084 | O34: 4
A35: ORD-2024-629525 | B35: 45400 | C35: 45420 | D35: Europe | E35: United Kingdom | F35: London | G35: Non-Profit | I35: D. Smith | J35: Laptops | K35: LAP-9932 | L35: 645.33 | M35: 1321.85 | N35: 0 | O35: 10
A36: ORD-2024-167215 | B36: 45527 | C36: 45525 | D36: Africa | E36: South Africa | F36: Johannesburg | G36: Education | H36: Retail | I36: E. Garcia | J36: Components | K36: CMP-1559 | L36: 1432.52 | M36: 3036.87 | N36: 0 | O36: 9
A37: ORD-2023-864121 | B37: 45012 | C37: 45038 | D37: Asia | E37: India | F37: Delhi | G37: Non-Profit | H37: Marketplace | I37: J. Njeri | J37: Printers | K37: PRN-4506 | L37: 178.53 | M37: 199.37 | N37: 0.101 | O37: 37
A38: ORD-2024-692673 | B38: 45358 | C38: 45376 | D38: Europe | E38: Germany | F38: Munich | G38: Corporate | H38: Online | I38: B. Chen | J38: Components | K38: CMP-7617 | L38: 712.84 | M38: 927.51 | N38: 0.243 | O38: 27
A39: ORD-2025-718992 | B39: 45832 | C39: 45848 | D39: Asia | E39: China | F39: Shanghai | G39: Enterprise | H39: Direct | I39: N. Brown | J39: Components | K39: CMP-8390 | L39: 757.19 | M39: 1735.41 | N39: 0.136 | O39: 8
A40: ORD-2024-599522 | B40: 45401 | C40: 45418 | D40: Africa | E40: Nigeria | F40: Port Harcourt | G40: Non-Profit | H40: Online | I40: A. Patel | J40: Printers | K40: PRN-7303 | L40: 865.33 | M40: 1395.64 | N40: 0.175 | O40: 13
A41: ORD-2023-651638 | B41: 45094 | C41: 45101 | D41: Americas | E41: USA | F41: San Francisco | G41: Corporate | H41: Retail | I41: I. Johnson | J41: Printers | K41: PRN-6536 | L41: 313.99 | M41: 454.42 | N41: 0.129 | O41: 9
A42: ORD-2024-635626 | B42: 45531 | C42: 45554 | D42: Europe | E42: Germany | F42: Berlin | G42: Small Business | H42: Direct | I42: D. Smith | J42: Monitors | K42: MON-9967 | L42: 1024.01 | M42: 1580.97 | N42: 0.037 | O42: 27
A43: ORD-2024-296582 | B43: 45302 | C43: 45324 | D43: Africa | E43: South Africa | F43: Durban | G43: Consumer | H43: Online | I43: K. Singh | J43: Networking | K43: NET-1412 | L43: 1206.2 | M43: 1759.79 | N43: 0 | O43: 6
A44: ORD-2024-998320 | B44: 45590 | C44: 45610 | D44: Africa | E44: Kenya | F44: Mombasa | G44: Corporate | H44: Direct | I44: H. Kim | J44: Printers | K44: PRN-3143 | L44: 1396.48 | M44: 3204.5 | N44: 0.318 | O44: 14
A45: ORD-2025-820255 | B45: 45806 | C45: 45828 | D45: Europe | E45: Germany | F45: Berlin | G45: Corporate | H45: Direct | I45: A. Patel | J45: Printers | K45: PRN-9787 | L45: 483.47 | M45: 1135.43 | N45: 0.146 | O45: 11
A46: ORD-2024-389336 | B46: 45432 | C46: 45445 | D46: Americas | E46: Canada | F46: Vancouver | G46: Enterprise | H46: Marketplace | I46: K. Singh | J46: Components | K46: CMP-5946 | L46: 675.43 | M46: 996.36 | N46: 0.182 | O46: 22
A47: ORD-2023-308124 | B47: 45035 | C47: 45046 | D47: Asia | E47: India | F47: Delhi | G47: Small Business | H47: Retail | I47: A. Patel | J47: Networking | K47: NET-2062 | L47: 826.55 | M47: 1397.05 | N47: 0.169 | O47: 28
... A77: ORD-2023-722117 | B77: 45187 | C77: 45207 | D77: Asia | E77: India | F77: Delhi | G77: Small Business | H77: Direct | I77: B. Chen | J77: Components | K77: CMP-1009 | L77: 825.64 | M77: 1108.43 | N77: 0.114 | O77: 7
A78: ORD-2024-446699 | B78: 45532 | C78: 45560 | D78: Americas | E78: Brazil | F78: Rio de Janeiro | G78: Non-Profit | H78: Online | J78: Accessories | K78: ACC-4490 | L78: 1394.65 | M78: 3144.1 | N78: 0.134 | O78: 13
A79: ORD-2024-451005 | B79: 45473 | C79: 45471 | D79: Americas | E79: Brazil | F79: Rio de Janeiro | G79: Small Business | H79: Direct | I79: L. Okafor | J79: Accessories | K79: ACC-9162 | L79: 1112.98 | M79: 2095.73 | N79: 0.072 | O79: 17
A80: ORD-2023-290279 | B80: 45091 | C80: 45093 | D80: Europe | E80: United Kingdom | F80: Manchester | G80: Non-Profit | H80: Direct | I80: K. Singh | J80: Components | K80: CMP-5820 | L80: 357.36 | M80: 703.62 | N80: 0.257 | O80: 20
A81: ORD-2024-192263 | B81: 45617 | C81: 45647 | D81: Europe | E81: France | F81: Marseille | G81: Small Business | H81: Direct | I81: I. Johnson | J81: Monitors | K81: MON-7943 | L81: 1122.68 | M81: 1997.19 | N81: 0.186 | O81: 3
A82: ORD-2023-159379 | B82: 44965 | C82: 44968 | D82: Africa | E82: South Africa | F82: Cape Town | G82: Corporate | H82: Direct | I82: M. Rossi | J82: Networking | K82: NET-5018 | L82: 1410.05 | M82: 2763.95 | N82: 0.161 | O82: 26
A83: ORD-2023-343322 | B83: 45157 | C83: 45181 | D83: Americas | E83: Canada | F83: Vancouver | G83: Enterprise | H83: Retail | I83: I. Johnson | J83: Printers | K83: PRN-9669 | L83: 1183.95 | M83: 1503.53 | N83: 0.241 | O83: 16
A84: ORD-2025-114382 | B84: 45791 | C84: 45801 | D84: Europe | E84: France | F84: Paris | G84: Small Business | H84: Marketplace | I84: K. Singh | J84: Components | K84: CMP-2865 | L84: 170.39 | M84: 388.04 | N84: 0.084 | O84: 15
A85: ORD-2025-488349 | B85: 45770 | C85: 45769 | D85: Americas | E85: USA | F85: San Francisco | G85: Non-Profit | H85: Distributor | I85: D. Smith | J85: Monitors | K85: MON-3371 | L85: 23.24 | M85: 44.57 | N85: 0.215 | O85: 15
A86: ORD-2025-330203 | B86: 45741 | C86: 45764 | D86: Europe | E86: United Kingdom | F86: London | G86: Consumer | H86: Retail | I86: H. Kim | J86: Networking | K86: NET-7166 | L86: 1421.19 | M86: 1808.26 | N86: 0.104 | O86: 13
A87: ORD-2023-841426 | B87: 45282 | C87: 45283 | D87: Africa | E87: South Africa | F87: Cape Town | G87: Non-Profit | H87: Marketplace | I87: D. Smith | J87: Components | K87: CMP-4531 | L87: 1186.18 | M87: 1285.09 | N87: 0.07 | O87: 11
A88: ORD-2024-594592 | B88: 45388 | C88: 45407 | D88: Asia | E88: China | F88: Shanghai | G88: Corporate | H88: Retail | I88: K. Singh | J88: Components | K88: CMP-8196 | L88: 1366.48 | M88: 1678.14 | N88: 0.154 | O88: 10
A89: ORD-2025-863978 | B89: 45876 | C89: 45888 | D89: Africa | E89: Kenya | F89: Nakuru | G89: Corporate | I89: M. Rossi | J89: Components | K89: CMP-2854 | L89: 601.51 | M89: 679.35 | N89: 0.188 | O89: 3
...

Sheet Brief
A1: Assignment
A2: Excel Mastery Assignment: Sales Operations & Analytics
A4: Overview:
A5: You are an analyst for a multi-regional electronics distributor. The 'Data' sheet contains 632 rows and 15 columns of transactional data with intentional data-quality issues.
A6: Your job is to clean, enrich, analyze, and present insights via a dynamic dashboard.
A8: Part A — Data Cleaning & Preparation:
A9: 1) Create a staging table where you:
A10: • Remove exact duplicate rows (define and document your duplicate criteria).
A11: • Fix data types (dates as Dates, numeric fields as numbers).
A12: • Handle missing values for City, Salesperson, and Channel using reasonable business logic (document your approach).
A13: • Flag and correct suspicious UnitPrice values (e.g., negative prices) and discounts (e.g., > 30%).
A14: • Ensure RequiredDate is not earlier than OrderDate; where it is, impute a corrected RequiredDate (explain your rule).
... A67: 15) Ensure your dashboard responds to slicers without broken references.

Sheet Staging_Table(Part A(1))
A1: OrderID | B1: Duplicate | C1: OrderDate | D1: RequiredDate | E1: FlaggedRequiredDate | F1: FixedRequiredDate | G1: LeadTimeDays | H1: Region | I1: Country | J1: City | K1: FixedCity | L1: CustomerSegment | M1: Channel | N1: FixedChannel | O1: Salesperson | P1: FixedSalesperson | Q1: ProductCategory | R1: SKU | S1: UnitCost | T1: UnitPrice | U1: AbsoluteUnitPrice | V1: DiscountPct | W1: Discount Fixed | X1: Quantity
A2: ORD-2023-723587 | B2: =IF(COUNTIF($A$2:A2,A2)=1,"Original","Duplicate") -> Original | C2: 44928 | D2: 44931 | E2: =IF(D2<C2,"Invalid","Valid") -> Valid | F2: =IF(D2>C2,D2,WORKDAY(C2,5)) -> 44931 | G2: =F2-C2 -> 3 | H2: Americas | I2: Canada | J2: Toronto | K2: =IF(J2="", "Unknown", J2) -> Toronto | L2: Corporate | M2: Distributor | N2: =IF(M2="", "Unknown", M2) -> Distributor | O2: B. Chen | P2: =IF(O2="","Unassigned",O2) -> B. Chen | Q2: Laptops | R2: LAP-8555 | S2: 315.87 | T2: 591.68 | U2: =IF(T2>0,T2,S2*1.2) -> 591.68 | V2: 0 | W2: =IF(V2<0.3,V2,0.3) -> 0 | X2: 7
A3: ORD-2023-689428 | B3: =IF(COUNTIF($A$2:A3,A3)=1,"Original","Duplicate") -> Original | C3: 44933 | D3: 44956 | E3: =IF(D3<C3,"Invalid","Valid") -> Valid | F3: =IF(D3>C3,D3,WORKDAY(C3,5)) -> 44956 | G3: =F3-C3 -> 23 | H3: Africa | I3: South Africa | J3: Cape Town | K3: =IF(J3="", "Unknown", J3) -> Cape Town | L3: Consumer | M3: Online | N3: =IF(M3="", "Unknown", M3) -> Online | O3: A. Patel | P3: =IF(O3="","Unassigned",O3) -> A. Patel | Q3: Printers | R3: PRN-4787 | S3: 299.02 | T3: 724.7 | U3: =IF(T3>0,T3,S3*1.2) -> 724.7 | V3: 0.14 | W3: =IF(V3<0.3,V3,0.3) -> 0.14 | X3: 5
A4: ORD-2023-884192 | B4: =IF(COUNTIF($A$2:A4,A4)=1,"Original","Duplicate") -> Original | C4: 44936 | D4: 44955 | E4: =IF(D4<C4,"Invalid","Valid") -> Valid | F4: =IF(D4>C4,D4,WORKDAY(C4,5)) -> 44955 | G4: =F4-C4 -> 19 | H4: Europe | I4: France | J4: Lyon | K4: =IF(J4="", "Unknown", J4) -> Lyon | L4: Non-Profit | M4: Direct | N4: =IF(M4="", "Unknown", M4) -> Direct | O4: D. Smith | P4: =IF(O4="","Unassigned",O4) -> D. Smith | Q4: Laptops | R4: LAP-4551 | S4: 401.66 | T4: 772.09 | U4: =IF(T4>0,T4,S4*1.2) -> 772.09 | V4: 0.089 | W4: =IF(V4<0.3,V4,0.3) -> 0.089 | X4: 14
A5: ORD-2023-700699 | B5: =IF(COUNTIF($A$2:A5,A5)=1,"Original","Duplicate") -> Original | C5: 44938 | D5: 44952 | E5: =IF(D5<C5,"Invalid","Valid") -> Valid | F5: =IF(D5>C5,D5,WORKDAY(C5,5)) -> 44952 | G5: =F5-C5 -> 14 | H5: Asia | I5: China | J5: Shenzhen | K5: =IF(J5="", "Unknown", J5) -> Shenzhen | L5: Non-Profit | M5: Retail | N5: =IF(M5="", "Unknown", M5) -> Retail | O5: M. Rossi | P5: =IF(O5="","Unassigned",O5) -> M. Rossi | Q5: Printers | R5: PRN-1641 | S5: 1083.09 | T5: 1425.87 | U5: =IF(T5>0,T5,S5*1.2) -> 1425.87 | V5: 0 | W5: =IF(V5<0.3,V5,0.3) -> 0 | X5: 8
A6: ORD-2023-382017 | B6: =IF(COUNTIF($A$2:A6,A6)=1,"Original","Duplicate") -> Original | C6: 44939 | D6: 44945 | E6: =IF(D6<C6,"Invalid","Valid") -> Valid | F6: =IF(D6>C6,D6,WORKDAY(C6,5)) -> 44945 | G6: =F6-C6 -> 6 | H6: Americas | I6: USA | J6: Chicago | K6: =IF(J6="", "Unknown", J6) -> Chicago | L6: Corporate | M6: Direct | N6: =IF(M6="", "Unknown", M6) -> Direct | O6: H. Kim | P6: =IF(O6="","Unassigned",O6) -> H. Kim | Q6: Phones | R6: PHN-3159 | S6: 833.57 | T6: 881.57 | U6: =IF(T6>0,T6,S6*1.2) -> 881.57 | V6: 0.057 | W6: =IF(V6<0.3,V6,0.3) -> 0.057 | X6: 18
A7: ORD-2023-112666 | B7: =IF(COUNTIF($A$2:A7,A7)=1,"Original","Duplicate") -> Original | C7: 44941 | D7: 44939 | E7: =IF(D7<C7,"Invalid","Valid") -> Invalid | F7: =IF(D7>C7,D7,WORKDAY(C7,5)) -> 44946 | G7: =F7-C7 -> 5 | H7: Africa | I7: Nigeria | J7: Abuja | K7: =IF(J7="", "Unknown", J7) -> Abuja | L7: Education | M7: Online | N7: =IF(M7="", "Unknown", M7) -> Online | O7: O. Wang | P7: =IF(O7="","Unassigned",O7) -> O. Wang | Q7: Printers | R7: PRN-6276 | S7: 28.38 | T7: 47.22 | U7: =IF(T7>0,T7,S7*1.2) -> 47.22 | V7: 0.194 | W7: =IF(V7<0.3,V7,0.3) -> 0.194 | X7: 18
A8: ORD-2023-780206 | B8: =IF(COUNTIF($A$2:A8,A8)=1,"Original","Duplicate") -> Original | C8: 44945 | D8: 44960 | E8: =IF(D8<C8,"Invalid","Valid") -> Valid | F8: =IF(D8>C8,D8,WORKDAY(C8,5)) -> 44960 | G8: =F8-C8 -> 15 | H8: Europe | I8: United Kingdom | J8: London | K8: =IF(J8="", "Unknown", J8) -> London | L8: Enterprise | M8: Distributor | N8: =IF(M8="", "Unknown", M8) -> Distributor | O8: G. Dubois | P8: =IF(O8="","Unassigned",O8) -> G. Dubois | Q8: Accessories | R8: ACC-3645 | S8: 873.06 | T8: 2101.55 | U8: =IF(T8>0,T8,S8*1.2) -> 2101.55 | V8: 0.066 | W8: =IF(V8<0.3,V8,0.3) -> 0.066 | X8: 10
A9: ORD-2023-586275 | B9: =IF(COUNTIF($A$2:A9,A9)=1,"Original","Duplicate") -> Original | C9: 44946 | D9: 44960 | E9: =IF(D9<C9,"Invalid","Valid") -> Valid | F9: =IF(D9>C9,D9,WORKDAY(C9,5)) -> 44960 | G9: =F9-C9 -> 14 | H9: Africa | I9: Kenya | J9: Kisumu | K9: =IF(J9="", "Unknown", J9) -> Kisumu | L9: Corporate | M9: Retail | N9: =IF(M9="", "Unknown", M9) -> Retail | O9: M. Rossi | P9: =IF(O9="","Unassigned",O9) -> M. Rossi | Q9: Networking | R9: NET-6036 | S9: 884.36 | T9: 1545.34 | U9: =IF(T9>0,T9,S9*1.2) -> 1545.34 | V9: 0.243 | W9: =IF(V9<0.3,V9,0.3) -> 0.243 | X9: 41
A10: ORD-2023-521818 | B10: =IF(COUNTIF($A$2:A10,A10)=1,"Original","Duplicate") -> Original | C10: 44948 | D10: 44956 | E10: =IF(D10<C10,"Invalid","Valid") -> Valid | F10: =IF(D10>C10,D10,WORKDAY(C10,5)) -> 44956 | G10: =F10-C10 -> 8 | H10: Americas | I10: USA | J10: San Francisco | K10: =IF(J10="", "Unknown", J10) -> San Francisco | L10: Small Business | M10: Online | N10: =IF(M10="", "Unknown", M10) -> Online | O10: A. Patel | P10: =IF(O10="","Unassigned",O10) -> A. Patel | Q10: Networking | R10: NET-4155 | S10: 413.52 | T10: 1004.34 | U10: =IF(T10>0,T10,S10*1.2) -> 1004.34 | V10: 0.111 | W10: =IF(V10<0.3,V10,0.3) -> 0.111 | X10: 18
A11: ORD-2023-613317 | B11: =IF(COUNTIF($A$2:A11,A11)=1,"Original","Duplicate") -> Original | C11: 44948 | D11: 44947 | E11: =IF(D11<C11,"Invalid","Valid") -> Invalid | F11: =IF(D11>C11,D11,WORKDAY(C11,5)) -> 44953 | G11: =F11-C11 -> 5 | H11: Europe | I11: Germany | J11: Munich | K11: =IF(J11="", "Unknown", J11) -> Munich | L11: Corporate | M11: Direct | N11: =IF(M11="", "Unknown", M11) -> Direct | O11: F. Müller | P11: =IF(O11="","Unassigned",O11) -> F. Müller | Q11: Monitors | R11: MON-2537 | S11: 150.86 | T11: 346.96 | U11: =IF(T11>0,T11,S11*1.2) -> 346.96 | V11: 0.196 | W11: =IF(V11<0.3,V11,0.3) -> 0.196 | X11: 8
A12: ORD-2023-811823 | B12: =IF(COUNTIF($A$2:A12,A12)=1,"Original","Duplicate") -> Original | C12: 44952 | D12: 44972 | E12: =IF(D12<C12,"Invalid","Valid") -> Valid | F12: =IF(D12>C12,D12,WORKDAY(C12,5)) -> 44972 | G12: =F12-C12 -> 20 | H12: Europe | I12: Germany | J12: Berlin | K12: =IF(J12="", "Unknown", J12) -> Berlin | L12: Small Business | M12: Online | N12: =IF(M12="", "Unknown", M12) -> Online | O12: O. Wang | P12: =IF(O12="","Unassigned",O12) -> O. Wang | Q12: Networking | R12: NET-8787 | S12: 492.62 | T12: 366.7 | U12: =IF(T12>0,T12,S12*1.2) -> 366.7 | V12: 0.089 | W12: =IF(V12<0.3,V12,0.3) -> 0.089 | X12: 10
A13: ORD-2023-430904 | B13: =IF(COUNTIF($A$2:A13,A13)=1,"Original","Duplicate") -> Original | C13: 44953 | D13: 44957 | E13: =IF(D13<C13,"Invalid","Valid") -> Valid | F13: =IF(D13>C13,D13,WORKDAY(C13,5)) -> 44957 | G13: =F13-C13 -> 4 | H13: Europe | I13: United Kingdom | J13: Manchester | K13: =IF(J13="", "Unknown", J13) -> Manchester | L13: Enterprise | M13: Online | N13: =IF(M13="", "Unknown", M13) -> Online | O13: N. Brown | P13: =IF(O13="","Unassigned",O13) -> N. Brown | Q13: Laptops | R13: LAP-9782 | S13: 941.2 | T13: 668.02 | U13: =IF(T13>0,T13,S13*1.2) -> 668.02 | V13: 0.22 | W13: =IF(V13<0.3,V13,0.3) -> 0.22 | X13: 16
... A128: ORD-2023-292714 | B128: =IF(COUNTIF($A$2:A128,A128)=1,"Original","Duplicate") -> Original | C128: 45117 | D128: 45139 | E128: =IF(D128<C128,"Invalid","Valid") -> Valid | F128: =IF(D128>C128,D128,WORKDAY(C128,5)) -> 45139 | G128: =F128-C128 -> 22 | H128: Europe | I128: France | J128: Marseille | K128: =IF(J128="", "Unknown", J128) -> Marseille | L128: Consumer | M128: Marketplace | N128: =IF(M128="", "Unknown", M128) -> Marketplace | O128: B. Chen | P128: =IF(O128="","Unassigned",O128) -> B. Chen | Q128: Printers | R128: PRN-1504 | S128: 1303.56 | T128: 1791.37 | U128: =IF(T128>0,T128,S128*1.2) -> 1791.37 | V128: 0.126 | W128: =IF(V128<0.3,V128,0.3) -> 0.126 | X128: 22
A129: ORD-2023-825084 | B129: =IF(COUNTIF($A$2:A129,A129)=1,"Original","Duplicate") -> Original | C129: 45121 | D129: 45128 | E129: =IF(D129<C129,"Invalid","Valid") -> Valid | F129: =IF(D129>C129,D129,WORKDAY(C129,5)) -> 45128 | G129: =F129-C129 -> 7 | H129: Africa | I129: South Africa | J129: Durban | K129: =IF(J129="", "Unknown", J129) -> Durban | L129: Enterprise | M129: Marketplace | N129: =IF(M129="", "Unknown", M129) -> Marketplace | P129: =IF(O129="","Unassigned",O129) -> Unassigned | Q129: Monitors | R129: MON-1018 | S129: 620.74 | T129: 1330.07 | U129: =IF(T129>0,T129,S129*1.2) -> 1330.07 | V129: 0.299 | W129: =IF(V129<0.3,V129,0.3) -> 0.299 | X129: 28
A130: ORD-2023-479747 | B130: =IF(COUNTIF($A$2:A130,A130)=1,"Original","Duplicate") -> Original | C130: 45121 | D130: 45121 | E130: =IF(D130<C130,"Invalid","Valid") -> Valid | F130: =IF(D130>C130,D130,WORKDAY(C130,5)) -> 45128 | G130: =F130-C130 -> 7 | H130: Africa | I130: Nigeria | J130: Lagos | K130: =IF(J130="", "Unknown", J130) -> Lagos | L130: Education | M130: Retail | N130: =IF(M130="", "Unknown", M130) -> Retail | O130: I. Johnson | P130: =IF(O130="","Unassigned",O130) -> I. Johnson | Q130: Accessories | R130: ACC-5334 | S130: 956.38 | T130: 1454.22 | U130: =IF(T130>0,T130,S130*1.2) -> 1454.22 | V130: 0.039 | W130: =IF(V130<0.3,V130,0.3) -> 0.039 | X130: 19
A131: ORD-2023-569862 | B131: =IF(COUNTIF($A$2:A131,A131)=1,"Original","Duplicate") -> Original | C131: 45123 | D131: 45151 | E131: =IF(D131<C131,"Invalid","Valid") -> Valid | F131: =IF(D131>C131,D131,WORKDAY(C131,5)) -> 45151 | G131: =F131-C131 -> 28 | H131: Europe | I131: United Kingdom | J131: Manchester | K131: =IF(J131="", "Unknown", J131) -> Manchester | L131: Non-Profit | M131: Online | N131: =IF(M131="", "Unknown", M131) -> Online | O131: J. Njeri | P131: =IF(O131="","Unassigned",O131) -> J. Njeri | Q131: Laptops | R131: LAP-1178 | S131: 1039.03 | T131: 2545.81 | U131: =IF(T131>0,T131,S131*1.2) -> 2545.81 | V131: 0.216 | W131: =IF(V131<0.3,V131,0.3) -> 0.216 | X131: 21
A132: ORD-2023-369150 | B132: =IF(COUNTIF($A$2:A132,A132)=1,"Original","Duplicate") -> Original | C132: 45125 | D132: 45148 | E132: =IF(D132<C132,"Invalid","Valid") -> Valid | F132: =IF(D132>C132,D132,WORKDAY(C132,5)) -> 45148 | G132: =F132-C132 -> 23 | H132: Africa | I132: South Africa | J132: Johannesburg | K132: =IF(J132="", "Unknown", J132) -> Johannesburg | L132: Small Business | M132: Retail | N132: =IF(M132="", "Unknown", M132) -> Retail | O132: L. Okafor | P132: =IF(O132="","Unassigned",O132) -> L. Okafor | Q132: Components | R132: CMP-8659 | S132: 1271.56 | T132: 995.47 | U132: =IF(T132>0,T132,S132*1.2) -> 995.47 | V132: 0.192 | W132: =IF(V132<0.3,V132,0.3) -> 0.192 | X132: 13
A133: ORD-2023-594700 | B133: =IF(COUNTIF($A$2:A133,A133)=1,"Original","Duplicate") -> Original | C133: 45125 | D133: 45129 | E133: =IF(D133<C133,"Invalid","Valid") -> Valid | F133: =IF(D133>C133,D133,WORKDAY(C133,5)) -> 45129 | G133: =F133-C133 -> 4 | H133: Americas | I133: Brazil | J133: São Paulo | K133: =IF(J133="", "Unknown", J133) -> São Paulo | L133: Consumer | M133: Direct | N133: =IF(M133="", "Unknown", M133) -> Direct | O133: F. Müller | P133: =IF(O133="","Unassigned",O133) -> F. Müller | Q133: Networking | R133: NET-1699 | S133: 1269.55 | T133: 2071.1 | U133: =IF(T133>0,T133,S133*1.2) -> 2071.1 | V133: 0.129 | W133: =IF(V133<0.3,V133,0.3) -> 0.129 | X133: 22
A134: ORD-2023-825836 | B134: =IF(COUNTIF($A$2:A134,A134)=1,"Original","Duplicate") -> Original | C134: 45126 | D134: 45138 | E134: =IF(D134<C134,"Invalid","Valid") -> Valid | F134: =IF(D134>C134,D134,WORKDAY(C134,5)) -> 45138 | G134: =F134-C134 -> 12 | H134: Americas | I134: Brazil | J134: Rio de Janeiro | K134: =IF(J134="", "Unknown", J134) -> Rio de Janeiro | L134: Corporate | M134: Retail | N134: =IF(M134="", "Unknown", M134) -> Retail | O134: C. Otieno | P134: =IF(O134="","Unassigned",O134) -> C. Otieno | Q134: Monitors | R134: MON-7869 | S134: 1334.64 | T134: 2273.42 | U134: =IF(T134>0,T134,S134*1.2) -> 2273.42 | V134: 0.118 | W134: =IF(V134<0.3,V134,0.3) -> 0.118 | X134: 14
A135: ORD-2023-109927 | B135: =IF(COUNTIF($A$2:A135,A135)=1,"Original","Duplicate") -> Original | C135: 45129 | D135: 45128 | E135: =IF(D135<C135,"Invalid","Valid") -> Invalid | F135: =IF(D135>C135,D135,WORKDAY(C135,5)) -> 45135 | G135: =F135-C135 -> 6 | H135: Asia | I135: India | J135: Delhi | K135: =IF(J135="", "Unknown", J135) -> Delhi | L135: Small Business | M135: Distributor | N135: =IF(M135="", "Unknown", M135) -> Distributor | O135: E. Garcia | P135: =IF(O135="","Unassigned",O135) -> E. Garcia | Q135: Printers | R135: PRN-2301 | S135: 946.99 | T135: 2132.19 | U135: =IF(T135>0,T135,S135*1.2) -> 2132.19 | V135: 0.165 | W135: =IF(V135<0.3,V135,0.3) -> 0.165 | X135: 7
A136: ORD-2023-369160 | B136: =IF(COUNTIF($A$2:A136,A136)=1,"Original","Duplicate") -> Original | C136: 45131 | D136: 45151 | E136: =IF(D136<C136,"Invalid","Valid") -> Valid | F136: =IF(D136>C136,D136,WORKDAY(C136,5)) -> 45151 | G136: =F136-C136 -> 20 | H136: Americas | I136: Canada | J136: Montreal | K136: =IF(J136="", "Unknown", J136) -> Montreal | L136: Education | M136: Direct | N136: =IF(M136="", "Unknown", M136) -> Direct | O136: C. Otieno | P136: =IF(O136="","Unassigned",O136) -> C. Otieno | Q136: Monitors | R136: MON-3307 | S136: 1082.38 | T136: 1766.55 | U136: =IF(T136>0,T136,S136*1.2) -> 1766.55 | V136: 0.164 | W136: =IF(V136<0.3,V136,0.3) -> 0.164 | X136: 20
A137: ORD-2023-261081 | B137: =IF(COUNTIF($A$2:A137,A137)=1,"Original","Duplicate") -> Original | C137: 45131 | D137: 45157 | E137: =IF(D137<C137,"Invalid","Valid") -> Valid | F137: =IF(D137>C137,D137,WORKDAY(C137,5)) -> 45157 | G137: =F137-C137 -> 26 | H137: Africa | I137: Kenya | J137: Nairobi | K137: =IF(J137="", "Unknown", J137) -> Nairobi | L137: Enterprise | M137: Distributor | N137: =IF(M137="", "Unknown", M137) -> Distributor | O137: M. Rossi | P137: =IF(O137="","Unassigned",O137) -> M. Rossi | Q137: Accessories | R137: ACC-1238 | S137: 661.45 | T137: 1634.86 | U137: =IF(T137>0,T137,S137*1.2) -> 1634.86 | V137: 0.565 | W137: =IF(V137<0.3,V137,0.3) -> 0.3 | X137: 24
A138: ORD-2023-660608 | B138: =IF(COUNTIF($A$2:A138,A138)=1,"Original","Duplicate") -> Original | C138: 45132 | D138: 45148 | E138: =IF(D138<C138,"Invalid","Valid") -> Valid | F138: =IF(D138>C138,D138,WORKDAY(C138,5)) -> 45148 | G138: =F138-C138 -> 16 | H138: Africa | I138: Nigeria | J138: Port Harcourt | K138: =IF(J138="", "Unknown", J138) -> Port Harcourt | L138: Corporate | M138: Distributor | N138: =IF(M138="", "Unknown", M138) -> Distributor | O138: I. Johnson | P138: =IF(O138="","Unassigned",O138) -> I. Johnson | Q138: Accessories | R138: ACC-8178 | S138: 506.83 | T138: 441.74 | U138: =IF(T138>0,T138,S138*1.2) -> 441.74 | V138: 0.24 | W138: =IF(V138<0.3,V138,0.3) -> 0.24 | X138: 9
A139: ORD-2023-912395 | B139: =IF(COUNTIF($A$2:A139,A139)=1,"Original","Duplicate") -> Original | C139: 45133 | D139: 45163 | E139: =IF(D139<C139,"Invalid","Valid") -> Valid | F139: =IF(D139>C139,D139,WORKDAY(C139,5)) -> 45163 | G139: =F139-C139 -> 30 | H139: Americas | I139: USA | J139: New York | K139: =IF(J139="", "Unknown", J139) -> New York | L139: Consumer | M139: Retail | N139: =IF(M139="", "Unknown", M139) -> Retail | O139: M. Rossi | P139: =IF(O139="","Unassigned",O139) -> M. Rossi | Q139: Accessories | R139: ACC-7078 | S139: 1261.48 | T139: 1643.18 | U139: =IF(T139>0,T139,S139*1.2) -> 1643.18 | V139: 0.151 | W139: =IF(V139<0.3,V139,0.3) -> 0.151 | X139: 23
A140: ORD-2023-290237 | B140: =IF(COUNTIF($A$2:A140,A140)=1,"Original","Duplicate") -> Original | C140: 45137 | D140: 45145 | E140: =IF(D140<C140,"Invalid","Valid") -> Valid | F140: =IF(D140>C140,D140,WORKDAY(C140,5)) -> 45145 | G140: =F140-C140 -> 8 | H140: Asia | I140: Japan | J140: Nagoya | K140: =IF(J140="", "Unknown", J140) -> Nagoya | L140: Education | M140: Marketplace | N140: =IF(M140="", "Unknown", M140) -> Marketplace | O140: A. Patel | P140: =IF(O140="","Unassigned",O140) -> A. Patel | Q140: Networking | R140: NET-1645 | S140: 1352.44 | T140: 2698.01 | U140: =IF(T140>0,T140,S140*1.2) -> 2698.01 | V140: 0.131 | W140: =IF(V140<0.3,V140,0.3) -> 0.131 | X140: 13
A141: ORD-2023-451931 | B141: =IF(COUNTIF($A$2:A141,A141)=1,"Original","Duplicate") -> Original | C141: 45137 | D141: 45157 | E141: =IF(D141<C141,"Invalid","Valid") -> Valid | F141: =IF(D141>C141,D141,WORKDAY(C141,5)) -> 45157 | G141: =F141-C141 -> 20 | H141: Europe | I141: France | J141: Paris | K141: =IF(J141="", "Unknown", J141) -> Paris | L141: Enterprise | M141: Marketplace | N141: =IF(M141="", "Unknown", M141) -> Marketplace | O141: G. Dubois | P141: =IF(O141="","Unassigned",O141) -> G. Dubois | Q141: Networking | R141: NET-5423 | S141: 1418.51 | T141: 2789.61 | U141: =IF(T141>0,T141,S141*1.2) -> 2789.61 | V141: 0.171 | W141: =IF(V141<0.3,V141,0.3) -> 0.171 | X141: 8
... A145: ORD-2023-548934 | B145: =IF(COUNTIF($A$2:A145,A145)=1,"Original","Duplicate") -> Original | C145: 45141 | D145: 45168 | E145: =IF(D145<C145,"Invalid","Valid") -> Valid | F145: =IF(D145>C145,D145,WORKDAY(C145,5)) -> 45168 | G145: =F145-C145 -> 27 | H145: Asia | I145: China | J145: Shanghai | K145: =IF(J145="", "Unknown", J145) -> Shanghai | L145: Consumer | M145: Distributor | N145: =IF(M145="", "Unknown", M145) -> Distributor | O145: N. Brown | P145: =IF(O145="","Unassigned",O145) -> N. Brown | Q145: Monitors | R145: MON-3773 | S145: 226.04 | T145: 545.72 | U145: =IF(T145>0,T145,S145*1.2) -> 545.72 | V145: 0.151 | W145: =IF(V145<0.3,V145,0.3) -> 0.151 | X145: 11
A146: ORD-2023-630430 | B146: =IF(COUNTIF($A$2:A146,A146)=1,"Original","Duplicate") -> Original | C146: 45142 | D146: 45162 | E146: =IF(D146<C146,"Invalid","Valid") -> Valid | F146: =IF(D146>C146,D146,WORKDAY(C146,5)) -> 45162 | G146: =F146-C146 -> 20 | H146: Americas | I146: Brazil | J146: Brasília | K146: =IF(J146="", "Unknown", J146) -> Brasília | L146: Non-Profit | M146: Direct | N146: =IF(M146="", "Unknown", M146) -> Direct | P146: =IF(O146="","Unassigned",O146) -> Unassigned | Q146: Networking | R146: NET-9125 | S146: 582.88 | T146: 1044.14 | U146: =IF(T146>0,T146,S146*1.2) -> 1044.14 | V146: 0.216 | W146: =IF(V146<0.3,V146,0.3) -> 0.216 | X146: 10
A147: ORD-2023-197661 | B147: =IF(COUNTIF($A$2:A147,A147)=1,"Original","Duplicate") -> Original | C147: 45146 | D147: 45160 | E147: =IF(D147<C147,"Invalid","Valid") -> Valid | F147: =IF(D147>C147,D147,WORKDAY(C147,5)) -> 45160 | G147: =F147-C147 -> 14 | H147: Europe | I147: United Kingdom | J147: Birmingham | K147: =IF(J147="", "Unknown", J147) -> Birmingham | L147: Non-Profit | M147: Direct | N147: =IF(M147="", "Unknown", M147) -> Direct | O147: N. Brown | P147: =IF(O147="","Unassigned",O147) -> N. Brown | Q147: Monitors | R147: MON-7511 | S147: 446.69 | T147: 967.25 | U147: =IF(T147>0,T147,S147*1.2) -> 967.25 | V147: 0.094 | W147: =IF(V147<0.3,V147,0.3) -> 0.094 | X147: 10
A148: ORD-2023-867175 | B148: =IF(COUNTIF($A$2:A148,A148)=1,"Original","Duplicate") -> Original | C148: 45148 | D148: 45153 | E148: =IF(D148<C148,"Invalid","Valid") -> Valid | F148: =IF(D148>C148,D148,WORKDAY(C148,5)) -> 45153 | G148: =F148-C148 -> 5 | H148: Americas | I148: Brazil | J148: São Paulo | K148: =IF(J148="", "Unknown", J148) -> São Paulo | L148: Education | M148: Direct | N148: =IF(M148="", "Unknown", M148) -> Direct | O148: G. Dubois | P148: =IF(O148="","Unassigned",O148) -> G. Dubois | Q148: Networking | R148: NET-2894 | S148: 1307.52 | T148: 1921.65 | U148: =IF(T148>0,T148,S148*1.2) -> 1921.65 | V148: 0.123 | W148: =IF(V148<0.3,V148,0.3) -> 0.123 | X148: 13
A149: ORD-2023-883066 | B149: =IF(COUNTIF($A$2:A149,A149)=1,"Original","Duplicate") -> Original | C149: 45150 | D149: 45175 | E149: =IF(D149<C149,"Invalid","Valid") -> Valid | F149: =IF(D149>C149,D149,WORKDAY(C149,5)) -> 45175 | G149: =F149-C149 -> 25 | H149: Asia | I149: China | J149: Shanghai | K149: =IF(J149="", "Unknown", J149) -> Shanghai | L149: Small Business | M149: Retail | N149: =IF(M149="", "Unknown", M149) -> Retail | O149: B. Chen | P149: =IF(O149="","Unassigned",O149) -> B. Chen | Q149: Components | R149: CMP-6352 | S149: 950.77 | T149: 694.78 | U149: =IF(T149>0,T149,S149*1.2) -> 694.78 | V149: 0.084 | W149: =IF(V149<0.3,V149,0.3) -> 0.084 | X149: 14
A150: ORD-2023-133848 | B150: =IF(COUNTIF($A$2:A150,A150)=1,"Original","Duplicate") -> Original | C150: 45153 | D150: 45176 | E150: =IF(D150<C150,"Invalid","Valid") -> Valid | F150: =IF(D150>C150,D150,WORKDAY(C150,5)) -> 45176 | G150: =F150-C150 -> 23 | H150: Americas | I150: USA | J150: New York | K150: =IF(J150="", "Unknown", J150) -> New York | L150: Enterprise | M150: Online | N150: =IF(M150="", "Unknown", M150) -> Online | O150: K. Singh | P150: =IF(O150="","Unassigned",O150) -> K. Singh | Q150: Phones | R150: PHN-2013 | S150: 590.33 | T150: 973.04 | U150: =IF(T150>0,T150,S150*1.2) -> 973.04 | V150: 0 | W150: =IF(V150<0.3,V150,0.3) -> 0 | X150: 26
A151: ORD-2023-274037 | B151: =IF(COUNTIF($A$2:A151,A151)=1,"Original","Duplicate") -> Original | C151: 45153 | D151: 45163 | E151: =IF(D151<C151,"Invalid","Valid") -> Valid | F151: =IF(D151>C151,D151,WORKDAY(C151,5)) -> 45163 | G151: =F151-C151 -> 10 | H151: Africa | I151: Kenya | J151: Nairobi | K151: =IF(J151="", "Unknown", J151) -> Nairobi | L151: Small Business | M151: Retail | N151: =IF(M151="", "Unknown", M151) -> Retail | O151: N. Brown | P151: =IF(O151="","Unassigned",O151) -> N. Brown | Q151: Phones | R151: PHN-1234 | S151: 91.85 | T151: 111.29 | U151: =IF(T151>0,T151,S151*1.2) -> 111.29 | V151: 0 | W151: =IF(V151<0.3,V151,0.3) -> 0 | X151: 6
A152: ORD-2023-525643 | B152: =IF(COUNTIF($A$2:A152,A152)=1,"Original","Duplicate") -> Original | C152: 45155 | D152: 45172 | E152: =IF(D152<C152,"Invalid","Valid") -> Valid | F152: =IF(D152>C152,D152,WORKDAY(C152,5)) -> 45172 | G152: =F152-C152 -> 17 | H152: Africa | I152: South Africa | J152: Durban | K152: =IF(J152="", "Unknown", J152) -> Durban | L152: Enterprise | M152: Retail | N152: =IF(M152="", "Unknown", M152) -> Retail | O152: A. Patel | P152: =IF(O152="","Unassigned",O152) -> A. Patel | Q152: Phones | R152: PHN-8072 | S152: 676.37 | T152: 1276.67 | U152: =IF(T152>0,T152,S152*1.2) -> 1276.67 | V152: 0.066 | W152: =IF(V152<0.3,V152,0.3) -> 0.066 | X152: 10
A153: ORD-2023-749324 | B153: =IF(COUNTIF($A$2:A153,A153)=1,"Original","Duplicate") -> Original | C153: 45157 | D153: 45176 | E153: =IF(D153<C153,"Invalid","Valid") -> Valid | F153: =IF(D153>C153,D153,WORKDAY(C153,5)) -> 45176 | G153: =F153-C153 -> 19 | H153: Africa | I153: South Africa | J153: Johannesburg | K153: =IF(J153="", "Unknown", J153) -> Johannesburg | L153: Enterprise | M153: Retail | N153: =IF(M153="", "Unknown", M153) -> Retail | O153: D. Smith | P153: =IF(O153="","Unassigned",O153) -> D. Smith | Q153: Monitors | R153: MON-2296 | S153: 494.61 | T153: 605.23 | U153: =IF(T153>0,T153,S153*1.2) -> 605.23 | V153: 0.204 | W153: =IF(V153<0.3,V153,0.3) -> 0.204 | X153: 18
A154: ORD-2023-343322 | B154: =IF(COUNTIF($A$2:A154,A154)=1,"Original","Duplicate") -> Original | C154: 45157 | D154: 45181 | E154: =IF(D154<C154,"Invalid","Valid") -> Valid | F154: =IF(D154>C154,D154,WORKDAY(C154,5)) -> 45181 | G154: =F154-C154 -> 24 | H154: Americas | I154: Canada | J154: Vancouver | K154: =IF(J154="", "Unknown", J154) -> Vancouver | L154: Enterprise | M154: Retail | N154: =IF(M154="", "Unknown", M154) -> Retail | O154: I. Johnson | P154: =IF(O154="","Unassigned",O154) -> I. Johnson | Q154: Printers | R154: PRN-9669 | S154: 1183.95 | T154: 1503.53 | U154: =IF(T154>0,T154,S154*1.2) -> 1503.53 | V154: 0.241 | W154: =IF(V154<0.3,V154,0.3) -> 0.241 | X154: 16
A155: ORD-2023-334213 | B155: =IF(COUNTIF($A$2:A155,A155)=1,"Original","Duplicate") -> Original | C155: 45157 | D155: 45161 | E155: =IF(D155<C155,"Invalid","Valid") -> Valid | F155: =IF(D155>C155,D155,WORKDAY(C155,5)) -> 45161 | G155: =F155-C155 -> 4 | H155: Africa | I155: Nigeria | J155: Abuja | K155: =IF(J155="", "Unknown", J155) -> Abuja | L155: Small Business | M155: Online | N155: =IF(M155="", "Unknown", M155) -> Online | O155: J. Njeri | P155: =IF(O155="","Unassigned",O155) -> J. Njeri | Q155: Monitors | R155: MON-5517 | S155: 790.63 | T155: 1382.31 | U155: =IF(T155>0,T155,S155*1.2) -> 1382.31 | V155: 0.101 | W155: =IF(V155<0.3,V155,0.3) -> 0.101 | X155: 7
A156: ORD-2023-603238 | B156: =IF(COUNTIF($A$2:A156,A156)=1,"Original","Duplicate") -> Original | C156: 45159 | D156: 45173 | E156: =IF(D156<C156,"Invalid","Valid") -> Valid | F156: =IF(D156>C156,D156,WORKDAY(C156,5)) -> 45173 | G156: =F156-C156 -> 14 | H156: Americas | I156: Canada | J156: Montreal | K156: =IF(J156="", "Unknown", J156) -> Montreal | L156: Education | M156: Distributor | N156: =IF(M156="", "Unknown", M156) -> Distributor | O156: F. Müller | P156: =IF(O156="","Unassigned",O156) -> F. Müller | Q156: Components | R156: CMP-2136 | S156: 178.19 | T156: 284.43 | U156: =IF(T156>0,T156,S156*1.2) -> 284.43 | V156: 0.089 | W156: =IF(V156<0.3,V156,0.3) -> 0.089 | X156: 8
A157: ORD-2023-375011 | B157: =IF(COUNTIF($A$2:A157,A157)=1,"Original","Duplicate") -> Original | C157: 45161 | D157: 45191 | E157: =IF(D157<C157,"Invalid","Valid") -> Valid | F157: =IF(D157>C157,D157,WORKDAY(C157,5)) -> 45191 | G157: =F157-C157 -> 30 | H157: Europe | I157: United Kingdom | J157: London | K157: =IF(J157="", "Unknown", J157) -> London | L157: Consumer | M157: Distributor | N157: =IF(M157="", "Unknown", M157) -> Distributor | O157: O. Wang | P157: =IF(O157="","Unassigned",O157) -> O. Wang | Q157: Accessories | R157: ACC-1492 | S157: 209.81 | T157: 523 | U157: =IF(T157>0,T157,S157*1.2) -> 523 | V157: 0.059 | W157: =IF(V157<0.3,V157,0.3) -> 0.059 | X157: 15
...

Sheet Part A (2&3)
A1: OrderID | B1: Duplicate | C1: OrderDate | D1: FixedRequiredDate | E1: LeadTimeDays | F1: Region | G1: Country | H1: City | I1: CustomerSegment | J1: Channel | K1: Salesperson | L1: ProductCategory | M1: SKU | N1: UnitCost | O1: UnitPrice | P1: DiscountPct | Q1: Quantity | R1: GrossRevenue | S1: CostofGoods | T1: GrossProfit | U1: MarginPct | V1: OrderDateNew | W1: OrderDateNew | X1: Quarters | Y1: RegionHierachy | Z1: ProductCategory | AA1: PriceBand | AB1: CohortStart | AC1: MonthsSinceStart | AE1: Category | AF1: Value | AG1: Percentile | AJ1: CohortStart
A2: ORD-2023-723587 | B2: =IF(COUNTIF($A$2:A2,A2)=1,"Original","Duplicate") -> Original | C2: 44928 | D2: 44931 | E2: =D2-C2 -> 3 | F2: Americas | G2: Canada | H2: Toronto | I2: Corporate | J2: Distributor | K2: B. Chen | L2: Laptops | M2: LAP-8555 | N2: 315.87 | O2: 591.68 | P2: 0 | Q2: 7 | R2: =(O2*Q2)*(1-P2) -> 4141.76 | S2: =N2*Q2 -> 2211.09 | T2: =R2-S2 -> 1930.67 | U2: =IF(R2=0,0,T2/R2) -> 0.46614724 | V2: =TEXT(C2,"MMM-YYYY") -> Jan-2023 | W2: =DATEVALUE(V2) -> 44927 | X2: ="Q"&ROUNDUP(MONTH(C2)/3,0)&"-"&YEAR(C2) -> Q1-2023 | Y2: =_xlfn.CONCAT(F2," ","→"," ",G2," ","→"," ",H2) -> Americas → Canada → Toronto | Z2: =TRIM(L2) -> Laptops | AA2: {=_xlfn.IFS(O2<=$AF$2,"Low",AND(O2>$AF$2,O2<$AF$3),"Medium",O2>=$AF$3,"High")} -> Low | AB2: =_xlfn.MINIFS($W$2:$W$632,$G$2:$G$632,G2) -> 44927 | AC2: {=(YEAR(W2:W632) - YEAR(AB2:AB632))*12 + (MONTH(W2:W632) - MONTH(AB2:AB632))} -> 0 | AE2: Low | AF2: =_xlfn.PERCENTILE.INC($O$2:$O$632,0.33) -> 824.755 | AG2: 0.33 | AJ2: =_xlfn.MINIFS($W$2:$W$632,$G$2:$G$632,G2) -> 44927
A3: ORD-2023-689428 | B3: =IF(COUNTIF($A$2:A3,A3)=1,"Original","Duplicate") -> Original | C3: 44933 | D3: 44956 | E3: =D3-C3 -> 23 | F3: Africa | G3: South Africa | H3: Cape Town | I3: Consumer | J3: Online | K3: A. Patel | L3: Printers | M3: PRN-4787 | N3: 299.02 | O3: 724.7 | P3: 0.14 | Q3: 5 | R3: =(O3*Q3)*(1-P3) -> 3116.21 | S3: =N3*Q3 -> 1495.1 | T3: =R3-S3 -> 1621.11 | U3: =IF(R3=0,0,T3/R3) -> 0.52021847 | V3: =TEXT(C3,"MMM-YYYY") -> Jan-2023 | W3: =DATEVALUE(V3) -> 44927 | X3: ="Q"&ROUNDUP(MONTH(C3)/3,0)&"-"&YEAR(C3) -> Q1-2023 | Y3: =_xlfn.CONCAT(F3," ","→"," ",G3," ","→"," ",H3) -> Africa → South Africa → Cape Town | Z3: =TRIM(L3) -> Printers | AA3: {=_xlfn.IFS(O3<=$AF$2,"Low",AND(O3>$AF$2,O3<$AF$3),"Medium",O3>=$AF$3,"High")} -> Low | AB3: =_xlfn.MINIFS($W$2:$W$632,$G$2:$G$632,G3) -> 44927 | AC3: 0 | AE3: High | AF3: =_xlfn.PERCENTILE.INC($O$2:$O$632,0.66) -> 1623.856 | AG3: 0.66 | AJ3: =_xlfn.MINIFS($W$2:$W$632,$G$2:$G$632,G3) -> 44927
A4: ORD-2023-884192 | B4: =IF(COUNTIF($A$2:A4,A4)=1,"Original","Duplicate") -> Original | C4: 44936 | D4: 44955 | E4: =D4-C4 -> 19 | F4: Europe | G4: France | H4: Lyon | I4: Non-Profit | J4: Direct | K4: D. Smith | L4: Laptops | M4: LAP-4551 | N4: 401.66 | O4: 772.09 | P4: 0.089 | Q4: 14 | R4: =(O4*Q4)*(1-P4) -> 9847.2359 | S4: =N4*Q4 -> 5623.24 | T4: =R4-S4 -> 4223.9959 | U4: =IF(R4=0,0,T4/R4) -> 0.42895244 | V4: =TEXT(C4,"MMM-YYYY") -> Jan-2023 | W4: =DATEVALUE(V4) -> 44927 | X4: ="Q"&ROUNDUP(MONTH(C4)/3,0)&"-"&YEAR(C4) -> Q1-2023 | Y4: =_xlfn.CONCAT(F4," ","→"," ",G4," ","→"," ",H4) -> Europe → France → Lyon | Z4: =TRIM(L4) -> Laptops | AA4: {=_xlfn.IFS(O4<=$AF$2,"Low",AND(O4>$AF$2,O4<$AF$3),"Medium",O4>=$AF$3,"High")} -> Low | AB4: =_xlfn.MINIFS($W$2:$W$632,$G$2:$G$632,G4) -> 44927 | AC4: 0 | AJ4: =_xlfn.MINIFS($W$2:$W$632,$G$2:$G$632,G4) -> 44927
A5: ORD-2023-700699 | B5: =IF(COUNTIF($A$2:A5,A5)=1,"Original","Duplicate") -> Original | C5: 44938 | D5: 44952 | E5: =D5-C5 -> 14 | F5: Asia | G5: China | H5: Shenzhen | I5: Non-Profit | J5: Retail | K5: M. Rossi | L5: Printers | M5: PRN-1641 | N5: 1083.09 | O5: 1425.87 | P5: 0 | Q5: 8 | R5: =(O5*Q5)*(1-P5) -> 11406.96 | S5: =N5*Q5 -> 8664.72 | T5: =R5-S5 -> 2742.24 | U5: =IF(R5=0,0,T5/R5) -> 0.2404006 | V5: =TEXT(C5,"MMM-YYYY") -> Jan-2023 | W5: =DATEVALUE(V5) -> 44927 | X5: ="Q"&ROUNDUP(MONTH(C5)/3,0)&"-"&YEAR(C5) -> Q1-2023 | Y5: =_xlfn.CONCAT(F5," ","→"," ",G5," ","→"," ",H5) -> Asia → China → Shenzhen | Z5: =TRIM(L5) -> Printers | AA5: {=_xlfn.IFS(O5<=$AF$2,"Low",AND(O5>$AF$2,O5<$AF$3),"Medium",O5>=$AF$3,"High")} -> Medium | AB5: =_xlfn.MINIFS($W$2:$W$632,$G$2:$G$632,G5) -> 44927 | AC5: 0 | AJ5: =_xlfn.MINIFS($W$2:$W$632,$G$2:$G$632,G5) -> 44927
A6: ORD-2023-382017 | B6: =IF(COUNTIF($A$2:A6,A6)=1,"Original","Duplicate") -> Original | C6: 44939 | D6: 44945 | E6: =D6-C6 -> 6 | F6: Americas | G6: USA | H6: Chicago | I6: Corporate | J6: Direct | K6: H. Kim | L6: Phones | M6: PHN-3159 | N6: 833.57 | O6: 881.57 | P6: 0.057 | Q6: 18 | R6: =(O6*Q6)*(1-P6) -> 14963.769 | S6: =N6*Q6 -> 15004.26 | T6: =R6-S6 -> -40.49082 | U6: =IF(R6=0,0,T6/R6) -> -0.0027059239 | V6: =TEXT(C6,"MMM-YYYY") -> Jan-2023 | W6: =DATEVALUE(V6) -> 44927 | X6: ="Q"&ROUNDUP(MONTH(C6)/3,0)&"-"&YEAR(C6) -> Q1-2023 | Y6: =_xlfn.CONCAT(F6," ","→"," ",G6," ","→"," ",H6) -> Americas → USA → Chicago | Z6: =TRIM(L6) -> Phones | AA6: {=_xlfn.IFS(O6<=$AF$2,"Low",AND(O6>$AF$2,O6<$AF$3),"Medium",O6>=$AF$3,"High")} -> Medium | AB6: =_xlfn.MINIFS($W$2:$W$632,$G$2:$G$632,G6) -> 44927 | AC6: 0 | AJ6: =_xlfn.MINIFS($W$2:$W$632,$G$2:$G$632,G6) -> 44927
A7: ORD-2023-112666 | B7: =IF(COUNTIF($A$2:A7,A7)=1,"Original","Duplicate") -> Original | C7: 44941 | D7: 44946 | E7: =D7-C7 -> 5 | F7: Africa | G7: Nigeria | H7: Abuja | I7: Education | J7: Online | K7: O. Wang | L7: Printers | M7: PRN-6276 | N7: 28.38 | O7: 47.22 | P7: 0.194 | Q7: 18 | R7: =(O7*Q7)*(1-P7) -> 685.06776 | S7: =N7*Q7 -> 510.84 | T7: =R7-S7 -> 174.22776 | U7: =IF(R7=0,0,T7/R7) -> 0.25432194 | V7: =TEXT(C7,"MMM-YYYY") -> Jan-2023 | W7: =DATEVALUE(V7) -> 44927 | X7: ="Q"&ROUNDUP(MONTH(C7)/3,0)&"-"&YEAR(C7) -> Q1-2023 | Y7: =_xlfn.CONCAT(F7," ","→"," ",G7," ","→"," ",H7) -> Africa → Nigeria → Abuja | Z7: =TRIM(L7) -> Printers | AA7: {=_xlfn.IFS(O7<=$AF$2,"Low",AND(O7>$AF$2,O7<$AF$3),"Medium",O7>=$AF$3,"High")} -> Low | AB7: =_xlfn.MINIFS($W$2:$W$632,$G$2:$G$632,G7) -> 44927 | AC7: 0 | AJ7: =_xlfn.MINIFS($W$2:$W$632,$G$2:$G$632,G7) -> 44927
A8: ORD-2023-780206 | B8: =IF(COUNTIF($A$2:A8,A8)=1,"Original","Duplicate") -> Original | C8: 44945 | D8: 44960 | E8: =D8-C8 -> 15 | F8: Europe | G8: United Kingdom | H8: London | I8: Enterprise | J8: Distributor | K8: G. Dubois | L8: Accessories | M8: ACC-3645 | N8: 873.06 | O8: 2101.55 | P8: 0.066 | Q8: 10 | R8: =(O8*Q8)*(1-P8) -> 19628.477 | S8: =N8*Q8 -> 8730.6 | T8: =R8-S8 -> 10897.877 | U8: =IF(R8=0,0,T8/R8) -> 0.55520747 | V8: =TEXT(C8,"MMM-YYYY") -> Jan-2023 | W8: =DATEVALUE(V8) -> 44927 | X8: ="Q"&ROUNDUP(MONTH(C8)/3,0)&"-"&YEAR(C8) -> Q1-2023 | Y8: =_xlfn.CONCAT(F8," ","→"," ",G8," ","→"," ",H8) -> Europe → United Kingdom → London | Z8: =TRIM(L8) -> Accessories | AA8: {=_xlfn.IFS(O8<=$AF$2,"Low",AND(O8>$AF$2,O8<$AF$3),"Medium",O8>=$AF$3,"High")} -> High | AB8: =_xlfn.MINIFS($W$2:$W$632,$G$2:$G$632,G8) -> 44927 | AC8: 0 | AJ8: =_xlfn.MINIFS($W$2:$W$632,$G$2:$G$632,G8) -> 44927
A9: ORD-2023-586275 | B9: =IF(COUNTIF($A$2:A9,A9)=1,"Original","Duplicate") -> Original | C9: 44946 | D9: 44960 | E9: =D9-C9 -> 14 | F9: Africa | G9: Kenya | H9: Kisumu | I9: Corporate | J9: Retail | K9: M. Rossi | L9: Networking | M9: NET-6036 | N9: 884.36 | O9: 1545.34 | P9: 0.243 | Q9: 41 | R9: =(O9*Q9)*(1-P9) -> 47962.718 | S9: =N9*Q9 -> 36258.76 | T9: =R9-S9 -> 11703.958 | U9: =IF(R9=0,0,T9/R9) -> 0.24402199 | V9: =TEXT(C9,"MMM-YYYY") -> Jan-2023 | W9: =DATEVALUE(V9) -> 44927 | X9: ="Q"&ROUNDUP(MONTH(C9)/3,0)&"-"&YEAR(C9) -> Q1-2023 | Y9: =_xlfn.CONCAT(F9," ","→"," ",G9," ","→"," ",H9) -> Africa → Kenya → Kisumu | Z9: =TRIM(L9) -> Networking | AA9: {=_xlfn.IFS(O9<=$AF$2,"Low",AND(O9>$AF$2,O9<$AF$3),"Medium",O9>=$AF$3,"High")} -> Medium | AB9: =_xlfn.MINIFS($W$2:$W$632,$G$2:$G$632,G9) -> 44927 | AC9: 0 | AJ9: =_xlfn.MINIFS($W$2:$W$632,$G$2:$G$632,G9) -> 44927
A10: ORD-2023-521818 | B10: =IF(COUNTIF($A$2:A10,A10)=1,"Original","Duplicate") -> Original | C10: 44948 | D10: 44956 | E10: =D10-C10 -> 8 | F10: Americas | G10: USA | H10: San Francisco | I10: Small Business | J10: Online | K10: A. Patel | L10: Networking | M10: NET-4155 | N10: 413.52 | O10: 1004.34 | P10: 0.111 | Q10: 18 | R10: =(O10*Q10)*(1-P10) -> 16071.449 | S10: =N10*Q10 -> 7443.36 | T10: =R10-S10 -> 8628.0887 | U10: =IF(R10=0,0,T10/R10) -> 0.53685818 | V10: =TEXT(C10,"MMM-YYYY") -> Jan-2023 | W10: =DATEVALUE(V10) -> 44927 | X10: ="Q"&ROUNDUP(MONTH(C10)/3,0)&"-"&YEAR(C10) -> Q1-2023 | Y10: =_xlfn.CONCAT(F10," ","→"," ",G10," ","→"," ",H10) -> Americas → USA → San Francisco | Z10: =TRIM(L10) -> Networking | AA10: {=_xlfn.IFS(O10<=$AF$2,"Low",AND(O10>$AF$2,O10<$AF$3),"Medium",O10>=$AF$3,"High")} -> Medium | AB10: =_xlfn.MINIFS($W$2:$W$632,$G$2:$G$632,G10) -> 44927 | AC10: 0 | AJ10: =_xlfn.MINIFS($W$2:$W$632,$G$2:$G$632,G10) -> 44927
A11: ORD-2023-613317 | B11: =IF(COUNTIF($A$2:A11,A11)=1,"Original","Duplicate") -> Original | C11: 44948 | D11: 44953 | E11: =D11-C11 -> 5 | F11: Europe | G11: Germany | H11: Munich | I11: Corporate | J11: Direct | K11: F. Müller | L11: Monitors | M11: MON-2537 | N11: 150.86 | O11: 346.96 | P11: 0.196 | Q11: 8 | R11: =(O11*Q11)*(1-P11) -> 2231.6467 | S11: =N11*Q11 -> 1206.88 | T11: =R11-S11 -> 1024.7667 | U11: =IF(R11=0,0,T11/R11) -> 0.45919756 | V11: =TEXT(C11,"MMM-YYYY") -> Jan-2023 | W11: =DATEVALUE(V11) -> 44927 | X11: ="Q"&ROUNDUP(MONTH(C11)/3,0)&"-"&YEAR(C11) -> Q1-2023 | Y11: =_xlfn.CONCAT(F11," ","→"," ",G11," ","→"," ",H11) -> Europe → Germany → Munich | Z11: =TRIM(L11) -> Monitors | AA11: {=_xlfn.IFS(O11<=$AF$2,"Low",AND(O11>$AF$2,O11<$AF$3),"Medium",O11>=$AF$3,"High")} -> Low | AB11: =_xlfn.MINIFS($W$2:$W$632,$G$2:$G$632,G11) -> 44927 | AC11: 0 | AJ11: =_xlfn.MINIFS($W$2:$W$632,$G$2:$G$632,G11) -> 44927
A12: ORD-2023-811823 | B12: =IF(COUNTIF($A$2:A12,A12)=1,"Original","Duplicate") -> Original | C12: 44952 | D12: 44972 | E12: =D12-C12 -> 20 | F12: Europe | G12: Germany | H12: Berlin | I12: Small Business | J12: Online | K12: O. Wang | L12: Networking | M12: NET-8787 | N12: 492.62 | O12: 366.7 | P12: 0.089 | Q12: 10 | R12: =(O12*Q12)*(1-P12) -> 3340.637 | S12: =N12*Q12 -> 4926.2 | T12: =R12-S12 -> -1585.563 | U12: =IF(R12=0,0,T12/R12) -> -0.47462894 | V12: =TEXT(C12,"MMM-YYYY") -> Jan-2023 | W12: =DATEVALUE(V12) -> 44927 | X12: ="Q"&ROUNDUP(MONTH(C12)/3,0)&"-"&YEAR(C12) -> Q1-2023 | Y12: =_xlfn.CONCAT(F12," ","→"," ",G12," ","→"," ",H12) -> Europe → Germany → Berlin | Z12: =TRIM(L12) -> Networking | AA12: {=_xlfn.IFS(O12<=$AF$2,"Low",AND(O12>$AF$2,O12<$AF$3),"Medium",O12>=$AF$3,"High")} -> Low | AB12: =_xlfn.MINIFS($W$2:$W$632,$G$2:$G$632,G12) -> 44927 | AC12: 0 | AJ12: =_xlfn.MINIFS($W$2:$W$632,$G$2:$G$632,G12) -> 44927
A13: ORD-2023-430904 | B13: =IF(COUNTIF($A$2:A13,A13)=1,"Original","Duplicate") -> Original | C13: 44953 | D13: 44957 | E13: =D13-C13 -> 4 | F13: Europe | G13: United Kingdom | H13: Manchester | I13: Enterprise | J13: Online | K13: N. Brown | L13: Laptops | M13: LAP-9782 | N13: 941.2 | O13: 668.02 | P13: 0.22 | Q13: 16 | R13: =(O13*Q13)*(1-P13) -> 8336.8896 | S13: =N13*Q13 -> 15059.2 | T13: =R13-S13 -> -6722.3104 | U13: =IF(R13=0,0,T13/R13) -> -0.80633314 | V13: =TEXT(C13,"MMM-YYYY") -> Jan-2023 | W13: =DATEVALUE(V13) -> 44927 | X13: ="Q"&ROUNDUP(MONTH(C13)/3,0)&"-"&YEAR(C13) -> Q1-2023 | Y13: =_xlfn.CONCAT(F13," ","→"," ",G13," ","→"," ",H13) -> Europe → United Kingdom → Manchester | Z13: =TRIM(L13) -> Laptops | AA13: {=_xlfn.IFS(O13<=$AF$2,"Low",AND(O13>$AF$2,O13<$AF$3),"Medium",O13>=$AF$3,"High")} -> Low | AB13: =_xlfn.MINIFS($W$2:$W$632,$G$2:$G$632,G13) -> 44927 | AC13: 0 | AJ13: =_xlfn.MINIFS($W$2:$W$632,$G$2:$G$632,G13) -> 44927
A14: ORD-2023-856322 | B14: =IF(COUNTIF($A$2:A14,A14)=1,"Original","Duplicate") -> Original | C14: 44955 | D14: 44963 | E14: =D14-C14 -> 8 | F14: Americas | G14: Brazil | H14: Brasília | I14: Corporate | J14: Marketplace | K14: D. Smith | L14: Monitors | M14: MON-7207 | N14: 41.84 | O14: 86.2 | P14: 0.226 | Q14: 27 | R14: =(O14*Q14)*(1-P14) -> 1801.4076 | S14: =N14*Q14 -> 1129.68 | T14: =R14-S14 -> 671.7276 | U14: =IF(R14=0,0,T14/R14) -> 0.3728904 | V14: =TEXT(C14,"MMM-YYYY") -> Jan-2023 | W14: =DATEVALUE(V14) -> 44927 | X14: ="Q"&ROUNDUP(MONTH(C14)/3,0)&"-"&YEAR(C14) -> Q1-2023 | Y14: =_xlfn.CONCAT(F14," ","→"," ",G14," ","→"," ",H14) -> Americas → Brazil → Brasília | Z14: =TRIM(L14) -> Monitors | AA14: {=_xlfn.IFS(O14<=$AF$2,"Low",AND(O14>$AF$2,O14<$AF$3),"Medium",O14>=$AF$3,"High")} -> Low | AB14: =_xlfn.MINIFS($W$2:$W$632,$G$2:$G$632,G14) -> 44927 | AC14: 0 | AJ14: =_xlfn.MINIFS($W$2:$W$632,$G$2:$G$632,G14) -> 44927
A15: ORD-2023-575584 | B15: =IF(COUNTIF($A$2:A15,A15)=1,"Original","Duplicate") -> Original | C15: 44956 | D15: 44978 | E15: =D15-C15 -> 22 | F15: Europe | G15: Germany | H15: Munich | I15: Small Business | J15: Marketplace | K15: G. Dubois | L15: Networking | M15: NET-3460 | N15: 1142.88 | O15: 1465.29 | P15: 0.186 | Q15: 7 | R15: =(O15*Q15)*(1-P15) -> 8349.2224 | S15: =N15*Q15 -> 8000.16 | T15: =R15-S15 -> 349.06242 | U15: =IF(R15=0,0,T15/R15) -> 0.041807776 | V15: =TEXT(C15,"MMM-YYYY") -> Jan-2023 | W15: =DATEVALUE(V15) -> 44927 | X15: ="Q"&ROUNDUP(MONTH(C15)/3,0)&"-"&YEAR(C15) -> Q1-2023 | Y15: =_xlfn.CONCAT(F15," ","→"," ",G15," ","→"," ",H15) -> Europe → Germany → Munich | Z15: =TRIM(L15) -> Networking | AA15: {=_xlfn.IFS(O15<=$AF$2,"Low",AND(O15>$AF$2,O15<$AF$3),"Medium",O15>=$AF$3,"High")} -> Medium | AB15: =_xlfn.MINIFS($W$2:$W$632,$G$2:$G$632,G15) -> 44927 | AC15: 0 | AJ15: =_xlfn.MINIFS($W$2:$W$632,$G$2:$G$632,G15) -> 44927
... A35: ORD-2023-276806 | B35: =IF(COUNTIF($A$2:A35,A35)=1,"Original","Duplicate") -> Original | C35: 44989 | D35: 45009 | E35: =D35-C35 -> 20 | F35: Americas | G35: Canada | H35: Montreal | I35: Consumer | J35: Distributor | K35: I. Johnson | L35: Laptops | M35: LAP-6160 | N35: 481.71 | O35: 912.45 | P35: 0.203 | Q35: 24 | R35: =(O35*Q35)*(1-P35) -> 17453.344 | S35: =N35*Q35 -> 11561.04 | T35: =R35-S35 -> 5892.3036 | U35: =IF(R35=0,0,T35/R35) -> 0.33760314 | V35: =TEXT(C35,"MMM-YYYY") -> Mar-2023 | W35: =DATEVALUE(V35) -> 44986 | X35: ="Q"&ROUNDUP(MONTH(C35)/3,0)&"-"&YEAR(C35) -> Q1-2023 | Y35: =_xlfn.CONCAT(F35," ","→"," ",G35," ","→"," ",H35) -> Americas → Canada → Montreal | Z35: =TRIM(L35) -> Laptops | AA35: {=_xlfn.IFS(O35<=$AF$2,"Low",AND(O35>$AF$2,O35<$AF$3),"Medium",O35>=$AF$3,"High")} -> Medium | AB35: =_xlfn.MINIFS($W$2:$W$632,$G$2:$G$632,G35) -> 44927 | AC35: 2 | AJ35: =_xlfn.MINIFS($W$2:$W$632,$G$2:$G$632,G35) -> 44927
A36: ORD-2023-854471 | B36: =IF(COUNTIF($A$2:A36,A36)=1,"Original","Duplicate") -> Original | C36: 44991 | D36: 45020 | E36: =D36-C36 -> 29 | F36: Asia | G36: China | H36: Beijing | I36: Small Business | J36: Direct | K36: C. Otieno | L36: Monitors | M36: MON-2073 | N36: 1126.29 | O36: 2050.87 | P36: 0.064 | Q36: 7 | R36: =(O36*Q36)*(1-P36) -> 13437.3 | S36: =N36*Q36 -> 7884.03 | T36: =R36-S36 -> 5553.2702 | U36: =IF(R36=0,0,T36/R36) -> 0.41327277 | V36: =TEXT(C36,"MMM-YYYY") -> Mar-2023 | W36: =DATEVALUE(V36) -> 44986 | X36: ="Q"&ROUNDUP(MONTH(C36)/3,0)&"-"&YEAR(C36) -> Q1-2023 | Y36: =_xlfn.CONCAT(F36," ","→"," ",G36," ","→"," ",H36) -> Asia → China → Beijing | Z36: =TRIM(L36) -> Monitors | AA36: {=_xlfn.IFS(O36<=$AF$2,"Low",AND(O36>$AF$2,O36<$AF$3),"Medium",O36>=$AF$3,"High")} -> High | AB36: =_xlfn.MINIFS($W$2:$W$632,$G$2:$G$632,G36) -> 44927 | AC36: 2
A37: ORD-2023-949710 | B37: =IF(COUNTIF($A$2:A37,A37)=1,"Original","Duplicate") -> Original | C37: 44992 | D37: 45017 | E37: =D37-C37 -> 25 | F37: Africa | G37: Kenya | H37: Nairobi | I37: Consumer | J37: Marketplace | K37: D. Smith | L37: Printers | M37: PRN-7049 | N37: 1024.1 | O37: 918.19 | P37: 0.189 | Q37: 10 | R37: =(O37*Q37)*(1-P37) -> 7446.5209 | S37: =N37*Q37 -> 10241 | T37: =R37-S37 -> -2794.4791 | U37: =IF(R37=0,0,T37/R37) -> -0.37527312 | V37: =TEXT(C37,"MMM-YYYY") -> Mar-2023 | W37: =DATEVALUE(V37) -> 44986 | X37: ="Q"&ROUNDUP(MONTH(C37)/3,0)&"-"&YEAR(C37) -> Q1-2023 | Y37: =_xlfn.CONCAT(F37," ","→"," ",G37," ","→"," ",H37) -> Africa → Kenya → Nairobi | Z37: =TRIM(L37) -> Printers | AA37: {=_xlfn.IFS(O37<=$AF$2,"Low",AND(O37>$AF$2,O37<$AF$3),"Medium",O37>=$AF$3,"High")} -> Medium | AB37: =_xlfn.MINIFS($W$2:$W$632,$G$2:$G$632,G37) -> 44927 | AC37: 2
A38: ORD-2023-281890 | B38: =IF(COUNTIF($A$2:A38,A38)=1,"Original","Duplicate") -> Original | C38: 44998 | D38: 45020 | E38: =D38-C38 -> 22 | F38: Africa | G38: South Africa | H38: Durban | I38: Small Business | J38: Retail | K38: A. Patel | L38: Components | M38: CMP-2574 | N38: 1113.7 | O38: 1620.6 | P38: 0.139 | Q38: 11 | R38: =(O38*Q38)*(1-P38) -> 15348.703 | S38: =N38*Q38 -> 12250.7 | T38: =R38-S38 -> 3098.0026 | U38: =IF(R38=0,0,T38/R38) -> 0.20184133 | V38: =TEXT(C38,"MMM-YYYY") -> Mar-2023 | W38: =DATEVALUE(V38) -> 44986 | X38: ="Q"&ROUNDUP(MONTH(C38)/3,0)&"-"&YEAR(C38) -> Q1-2023 | Y38: =_xlfn.CONCAT(F38," ","→"," ",G38," ","→"," ",H38) -> Africa → South Africa → Durban | Z38: =TRIM(L38) -> Components | AA38: {=_xlfn.IFS(O38<=$AF$2,"Low",AND(O38>$AF$2,O38<$AF$3),"Medium",O38>=$AF$3,"High")} -> Medium | AB38: =_xlfn.MINIFS($W$2:$W$632,$G$2:$G$632,G38) -> 44927 | AC38: 2
A39: ORD-2023-946143 | B39: =IF(COUNTIF($A$2:A39,A39)=1,"Original","Duplicate") -> Original | C39: 44999 | D39: 45015 | E39: =D39-C39 -> 16 | F39: Africa | G39: South Africa | H39: Cape Town | I39: Consumer | J39: Distributor | K39: K. Singh | L39: Components | M39: CMP-8230 | N39: 1309.77 | O39: 1589.07 | P39: 0.102 | Q39: 10 | R39: =(O39*Q39)*(1-P39) -> 14269.849 | S39: =N39*Q39 -> 13097.7 | T39: =R39-S39 -> 1172.1486 | U39: =IF(R39=0,0,T39/R39) -> 0.082141628 | V39: =TEXT(C39,"MMM-YYYY") -> Mar-2023 | W39: =DATEVALUE(V39) -> 44986 | X39: ="Q"&ROUNDUP(MONTH(C39)/3,0)&"-"&YEAR(C39) -> Q1-2023 | Y39: =_xlfn.CONCAT(F39," ","→"," ",G39," ","→"," ",H39) -> Africa → South Africa → Cape Town | Z39: =TRIM(L39) -> Components | AA39: {=_xlfn.IFS(O39<=$AF$2,"Low",AND(O39>$AF$2,O39<$AF$3),"Medium",O39>=$AF$3,"High")} -> Medium | AB39: =_xlfn.MINIFS($W$2:$W$632,$G$2:$G$632,G39) -> 44927 | AC39: 2
A40: ORD-2023-799597 | B40: =IF(COUNTIF($A$2:A40,A40)=1,"Original","Duplicate") -> Original | C40: 44999 | D40: 45003 | E40: =D40-C40 -> 4 | F40: Europe | G40: Germany | H40: Frankfurt | I40: Enterprise | J40: Direct | K40: A. Patel | L40: Components | M40: CMP-8675 | N40: 472.33 | O40: 360.34 | P40: 0.165 | Q40: 14 | R40: =(O40*Q40)*(1-P40) -> 4212.3746 | S40: =N40*Q40 -> 6612.62 | T40: =R40-S40 -> -2400.2454 | U40: =IF(R40=0,0,T40/R40) -> -0.56980816 | V40: =TEXT(C40,"MMM-YYYY") -> Mar-2023 | W40: =DATEVALUE(V40) -> 44986 | X40: ="Q"&ROUNDUP(MONTH(C40)/3,0)&"-"&YEAR(C40) -> Q1-2023 | Y40: =_xlfn.CONCAT(F40," ","→"," ",G40," ","→"," ",H40) -> Europe → Germany → Frankfurt | Z40: =TRIM(L40) -> Components | AA40: {=_xlfn.IFS(O40<=$AF$2,"Low",AND(O40>$AF$2,O40<$AF$3),"Medium",O40>=$AF$3,"High")} -> Low | AB40: =_xlfn.MINIFS($W$2:$W$632,$G$2:$G$632,G40) -> 44927 | AC40: 2
A41: ORD-2023-933238 | B41: =IF(COUNTIF($A$2:A41,A41)=1,"Original","Duplicate") -> Original | C41: 45002 | D41: 45022 | E41: =D41-C41 -> 20 | F41: Europe | G41: Germany | H41: Munich | I41: Consumer | J41: Retail | K41: O. Wang | L41: Phones | M41: PHN-8483 | N41: 692.18 | O41: 1159.35 | P41: 0.112 | Q41: 2 | R41: =(O41*Q41)*(1-P41) -> 2059.0056 | S41: =N41*Q41 -> 1384.36 | T41: =R41-S41 -> 674.6456 | U41: =IF(R41=0,0,T41/R41) -> 0.32765603 | V41: =TEXT(C41,"MMM-YYYY") -> Mar-2023 | W41: =DATEVALUE(V41) -> 44986 | X41: ="Q"&ROUNDUP(MONTH(C41)/3,0)&"-"&YEAR(C41) -> Q1-2023 | Y41: =_xlfn.CONCAT(F41," ","→"," ",G41," ","→"," ",H41) -> Europe → Germany → Munich | Z41: =TRIM(L41) -> Phones | AA41: {=_xlfn.IFS(O41<=$AF$2,"Low",AND(O41>$AF$2,O41<$AF$3),"Medium",O41>=$AF$3,"High")} -> Medium | AB41: =_xlfn.MINIFS($W$2:$W$632,$G$2:$G$632,G41) -> 44927 | AC41: 2
A42: ORD-2023-548874 | B42: =IF(COUNTIF($A$2:A42,A42)=1,"Original","Duplicate") -> Original | C42: 45004 | D42: 45025 | E42: =D42-C42 -> 21 | F42: Europe | G42: United Kingdom | H42: Manchester | I42: Consumer | J42: Retail | K42: L. Okafor | L42: Accessories | M42: ACC-9150 | N42: 1082.17 | O42: 1234.1 | P42: 0.189 | Q42: 16 | R42: =(O42*Q42)*(1-P42) -> 16013.682 | S42: =N42*Q42 -> 17314.72 | T42: =R42-S42 -> -1301.0384 | U42: =IF(R42=0,0,T42/R42) -> -0.081245427 | V42: =TEXT(C42,"MMM-YYYY") -> Mar-2023 | W42: =DATEVALUE(V42) -> 44986 | X42: ="Q"&ROUNDUP(MONTH(C42)/3,0)&"-"&YEAR(C42) -> Q1-2023 | Y42: =_xlfn.CONCAT(F42," ","→"," ",G42," ","→"," ",H42) -> Europe → United Kingdom → Manchester | Z42: =TRIM(L42) -> Accessories | AA42: {=_xlfn.IFS(O42<=$AF$2,"Low",AND(O42>$AF$2,O42<$AF$3),"Medium",O42>=$AF$3,"High")} -> Medium | AB42: =_xlfn.MINIFS($W$2:$W$632,$G$2:$G$632,G42) -> 44927 | AC42: 2
A43: ORD-2023-835010 | B43: =IF(COUNTIF($A$2:A43,A43)=1,"Original","Duplicate") -> Original | C43: 45008 | D43: 45031 | E43: =D43-C43 -> 23 | F43: Africa | G43: Kenya | H43: Mombasa | I43: Small Business | J43: Retail | K43: C. Otieno | L43: Accessories | M43: ACC-2988 | N43: 875.36 | O43: 1178.62 | P43: 0.151 | Q43: 53 | R43: =(O43*Q43)*(1-P43) -> 53034.364 | S43: =N43*Q43 -> 46394.08 | T43: =R43-S43 -> 6640.2841 | U43: =IF(R43=0,0,T43/R43) -> 0.1252072 | V43: =TEXT(C43,"MMM-YYYY") -> Mar-2023 | W43: =DATEVALUE(V43) -> 44986 | X43: ="Q"&ROUNDUP(MONTH(C43)/3,0)&"-"&YEAR(C43) -> Q1-2023 | Y43: =_xlfn.CONCAT(F43," ","→"," ",G43," ","→"," ",H43) -> Africa → Kenya → Mombasa | Z43: =TRIM(L43) -> Accessories | AA43: {=_xlfn.IFS(O43<=$AF$2,"Low",AND(O43>$AF$2,O43<$AF$3),"Medium",O43>=$AF$3,"High")} -> Medium | AB43: =_xlfn.MINIFS($W$2:$W$632,$G$2:$G$632,G43) -> 44927 | AC43: 2
A44: ORD-2023-240507 | B44: =IF(COUNTIF($A$2:A44,A44)=1,"Original","Duplicate") -> Original | C44: 45010 | D44: 45011 | E44: =D44-C44 -> 1 | F44: Asia | G44: Japan | H44: Osaka | I44: Small Business | J44: Distributor | K44: I. Johnson | L44: Monitors | M44: MON-9227 | N44: 135.12 | O44: 301.7 | P44: 0.14 | Q44: 47 | R44: =(O44*Q44)*(1-P44) -> 12194.714 | S44: =N44*Q44 -> 6350.64 | T44: =R44-S44 -> 5844.074 | U44: =IF(R44=0,0,T44/R44) -> 0.4792301 | V44: =TEXT(C44,"MMM-YYYY") -> Mar-2023 | W44: =DATEVALUE(V44) -> 44986 | X44: ="Q"&ROUNDUP(MONTH(C44)/3,0)&"-"&YEAR(C44) -> Q1-2023 | Y44: =_xlfn.CONCAT(F44," ","→"," ",G44," ","→"," ",H44) -> Asia → Japan → Osaka | Z44: =TRIM(L44) -> Monitors | AA44: {=_xlfn.IFS(O44<=$AF$2,"Low",AND(O44>$AF$2,O44<$AF$3),"Medium",O44>=$AF$3,"High")} -> Low | AB44: =_xlfn.MINIFS($W$2:$W$632,$G$2:$G$632,G44) -> 44986 | AC44: 0
A45: ORD-2023-864121 | B45: =IF(COUNTIF($A$2:A45,A45)=1,"Original","Duplicate") -> Original | C45: 45012 | D45: 45038 | E45: =D45-C45 -> 26 | F45: Asia | G45: India | H45: Delhi | I45: Non-Profit | J45: Marketplace | K45: J. Njeri | L45: Printers | M45: PRN-4506 | N45: 178.53 | O45: 199.37 | P45: 0.101 | Q45: 37 | R45: =(O45*Q45)*(1-P45) -> 6631.6443 | S45: =N45*Q45 -> 6605.61 | T45: =R45-S45 -> 26.03431 | U45: =IF(R45=0,0,T45/R45) -> 0.00392577 | V45: =TEXT(C45,"MMM-YYYY") -> Mar-2023 | W45: =DATEVALUE(V45) -> 44986 | X45: ="Q"&ROUNDUP(MONTH(C45)/3,0)&"-"&YEAR(C45) -> Q1-2023 | Y45: =_xlfn.CONCAT(F45," ","→"," ",G45," ","→"," ",H45) -> Asia → India → Delhi | Z45: =TRIM(L45) -> Printers | AA45: {=_xlfn.IFS(O45<=$AF$2,"Low",AND(O45>$AF$2,O45<$AF$3),"Medium",O45>=$AF$3,"High")} -> Low | AB45: =_xlfn.MINIFS($W$2:$W$632,$G$2:$G$632,G45) -> 44958 | AC45: 1
